Workbook

Sheet Instructions
A1: Commercial Proposal & Pricing Simulator — Excel Model
A3: This workbook is a decision-support tool for evaluating B2B industrial sales proposals.
A4: It is built around a fictional company, InduTech Solutions, and a fully synthetic dataset.
A6: How to use this workbook:
A7: 1. Go to the 'Pricing Calculator' sheet.
A8: 2. Edit the YELLOW cells only (Customer, Product, Quantity, Discount, Competitor Price, Payment Terms, Expected Delivery Days, Target Margin).
A9: 3. All other cells recalculate automatically using formulas (INDEX/MATCH lookups to Customers and Products, plus the pricing formulas below).
A10: 4. Check 'Scenario Analysis' for a 5%/10%/15%/20% discount comparison.
A11: 5. Check 'Risk Assessment' for the weighted commercial risk score.
A12: 6. 'Proposal Summary' auto-builds a presentable summary from the Pricing Calculator inputs.
A14: Core formulas:
A15: Revenue = Quantity x Quoted Unit Price
... A27: Limitations: dataset is synthetic; win probability and risk scores are simplified, configurable decision-support estimates, not guarantees or audited financial figures.

Sheet Customers
A1: Customer_ID | B1: Customer_Name | C1: Industry | D1: Region | E1: Annual_Revenue | F1: Customer_Tier | G1: Previous_Orders | H1: Average_Order_Value | I1: Historical_Win_Rate | J1: Payment_Reliability | K1: Average_Payment_Days | L1: Relationship_Years | M1: Strategic_Account | N1: Customer_Risk_Level
A2: CUST0001 | B2: IOCL Industries 1 | C2: Renewable Energy | D2: Middle East | E2: 169 | F2: Bronze | G2: 9 | H2: 0.688 | I2: 0.4 | J2: 74 | K2: 50 | L2: 4 | M2: 0 | N2: Medium
A3: CUST0002 | B3: BPCL Infra 2 | C3: Manufacturing | D3: SE Asia | E3: 754.9 | F3: Silver | G3: 3 | H3: 0.836 | I3: 0.5 | J3: 79 | K3: 44 | L3: 1 | M3: 0 | N3: Medium
A4: CUST0003 | B4: GAIL Infra 3 | C4: Oil & Gas | D4: South India | E4: 1745.2 | F4: Gold | G4: 9 | H4: 2.015 | I4: 0.68 | J4: 78 | K4: 48 | L4: 8 | M4: 1 | N4: Low
A5: CUST0004 | B5: Vedanta Power 4 | C5: Petrochemicals | D5: West India | E5: 234.9 | F5: Bronze | G5: 4 | H5: 0.948 | I5: 0.33 | J5: 67 | K5: 59 | L5: 3 | M5: 0 | N5: Medium
A6: CUST0005 | B6: GAIL Industries 5 | C6: Manufacturing | D6: East India | E6: 2103.1 | F6: Gold | G6: 15 | H6: 0.799 | I6: 0.71 | J6: 86 | K6: 39 | L6: 8 | M6: 1 | N6: Low
A7: CUST0006 | B7: JSW Infra 6 | C7: Power Generation | D7: South India | E7: 2436.1 | F7: Gold | G7: 3 | H7: 1.035 | I7: 0.67 | J7: 81 | K7: 40 | L7: 3 | M7: 1 | N7: Low
A8: CUST0007 | B8: NTPC Energy 7 | C8: Infrastructure | D8: West India | E8: 7334.2 | F8: Platinum | G8: 8 | H8: 0.976 | I8: 0.71 | J8: 95 | K8: 29 | L8: 7 | M8: 1 | N8: Low
A9: CUST0008 | B9: Sembcorp Projects 8 | C9: Power Generation | D9: Middle East | E9: 352.6 | F9: Silver | G9: 0 | H9: 0.356 | I9: 0.36 | J9: 67 | K9: 56 | L9: 0 | M9: 0 | N9: Medium
A10: CUST0009 | B10: Reliance Infra 9 | C10: Manufacturing | D10: Middle East | E10: 569.6 | F10: Silver | G10: 3 | H10: 1.035 | I10: 0.41 | J10: 78 | K10: 44 | L10: 2 | M10: 0 | N10: Medium
A11: CUST0010 | B11: GAIL Industries 10 | C11: Infrastructure | D11: North India | E11: 676.4 | F11: Silver | G11: 14 | H11: 0.429 | I11: 0.59 | J11: 76 | K11: 46 | L11: 7 | M11: 0 | N11: Low
A12: CUST0011 | B12: Adani Projects 11 | C12: Manufacturing | D12: East India | E12: 402.4 | F12: Silver | G12: 0 | H12: 0.076 | I12: 0.49 | J12: 71 | K12: 35 | L12: 0 | M12: 0 | N12: Medium
A13: CUST0012 | B13: ONGC Industries 12 | C13: Manufacturing | D13: Middle East | E13: 104.9 | F13: Bronze | G13: 13 | H13: 0.555 | I13: 0.43 | J13: 67 | K13: 44 | L13: 7 | M13: 0 | N13: Low
... A101: CUST0100 | B101: Vedanta Power 100 | C101: Power Generation | D101: West India | E101: 1793.9 | F101: Gold | G101: 15 | H101: 1.965 | I101: 0.32 | J101: 77 | K101: 43 | L101: 6 | M101: 0 | N101: Low

Sheet Products
A1: Product_ID | B1: Product_Name | C1: Product_Category | D1: Base_Cost | E1: Standard_Price | F1: Installation_Cost | G1: Warranty_Cost | H1: Maintenance_Cost | I1: Logistics_Cost | J1: Minimum_Margin | K1: Maximum_Discount
A2: PROD001 | B2: Industrial Pump | C2: Pumps | D2: 118214.43 | E2: 191665.7 | F2: 7063.14 | G2: 4113.79 | H2: 3156.89 | I2: 3204.08 | J2: 0.168 | K2: 0.234
A3: PROD002 | B3: Gas Compression Unit | C3: Gas Compression | D3: 277978.71 | E3: 415915.03 | F3: 25352.6 | G3: 5826.1 | H3: 8566.83 | I3: 13293.09 | J3: 0.161 | K3: 0.166
A4: PROD003 | B4: Turbomachinery Rotor | C4: Turbomachinery | D4: 450748.83 | E4: 687164.03 | F4: 33044.41 | G4: 9737.89 | H4: 12832.41 | I4: 23139.22 | J4: 0.133 | K4: 0.164
A5: PROD004 | B5: Turbomachinery Casing | C5: Turbomachinery | D5: 234813.44 | E5: 354973.32 | F5: 8635.67 | G5: 13594.01 | H5: 6152.06 | I5: 16093.68 | J5: 0.178 | K5: 0.158
A6: PROD005 | B6: Industrial Control Valve | C6: Valves | D6: 27808.43 | E6: 48628 | F6: 2068.85 | G6: 1033.39 | H6: 757.59 | I6: 616.07 | J6: 0.152 | K6: 0.249
A7: PROD006 | B7: Safety Relief Valve | C7: Valves | D7: 38554.76 | E7: 54063.98 | F7: 3061.47 | G7: 1236.47 | H7: 1778.13 | I7: 875.46 | J7: 0.176 | K7: 0.234
A8: PROD007 | B8: Annual Maintenance Contract | C8: Maintenance Services | D8: 14110.23 | E8: 19878.33 | F8: 0 | G8: 753.32 | H8: 229.01 | I8: 735.06 | J8: 0.175 | K8: 0.207
A9: PROD008 | B9: Field Installation Package | C9: Installation Services | D9: 28656.13 | E9: 44473.11 | F9: 0 | G9: 645.47 | H9: 1396.99 | I9: 1107.25 | J9: 0.131 | K9: 0.179
A10: PROD009 | B10: Spare Parts Kit - Pump | C10: Spare Parts | D10: 14501.22 | E10: 20599.16 | F10: 1315.42 | G10: 700.61 | H10: 626.46 | I10: 1139.13 | J10: 0.171 | K10: 0.244
A11: PROD010 | B11: Spare Parts Kit - Compressor | C11: Spare Parts | D11: 2777.09 | E11: 4749.47 | F11: 189.39 | G11: 115.92 | H11: 127.63 | I11: 217.47 | J11: 0.162 | K11: 0.198
A12: PROD011 | B12: Industrial Pump Model 2 | C12: Pumps | D12: 65640.39 | E12: 100318.18 | F12: 3630.7 | G12: 2340.75 | H12: 892.06 | I12: 1617.78 | J12: 0.167 | K12: 0.195
A13: PROD012 | B13: Gas Compression Unit Model 2 | C13: Gas Compression | D13: 568808.02 | E13: 923505.94 | F13: 18464.83 | G13: 14960.18 | H13: 10370.96 | I13: 44676.55 | J13: 0.133 | K13: 0.202
... A31: PROD030 | B31: Spare Parts Kit - Compressor Model 3 | C31: Spare Parts | D31: 6703.07 | E31: 10752.24 | F31: 460.18 | G31: 358.38 | H31: 96.16 | I31: 224.62 | J31: 0.168 | K31: 0.235

Sheet Historical Deals
A1: Deal_ID | B1: Customer_ID | C1: Product_ID | D1: Deal_Value | E1: Discount_Percentage | F1: Final_Price | G1: Cost | H1: Gross_Profit | I1: Margin_Percentage | J1: Competitor_Price_Index | K1: Sales_Cycle_Days | L1: Payment_Terms_Days | M1: Delivery_Delay_Days | N1: Won
A2: DEAL00001 | B2: CUST0078 | C2: PROD030 | D2: 43008.96 | E2: 0.0775 | F2: 39677.7 | G2: 31369.64 | H2: 8308.06 | I2: 0.2094 | J2: 1.067 | K2: 64 | L2: 30 | M2: 12 | N2: 0
A3: DEAL00002 | B3: CUST0088 | C3: PROD013 | D3: 2062838.4 | E3: 0.0398 | F3: 1980659.1 | G3: 1266474 | H3: 714185.03 | I3: 0.3606 | J3: 1.044 | K3: 67 | L3: 30 | M3: 1 | N3: 0
A4: DEAL00003 | B4: CUST0077 | C4: PROD013 | D4: 1031419.2 | E4: 0.0441 | F4: 985952.76 | G4: 633237.02 | H4: 352715.74 | I4: 0.3577 | J4: 0.942 | K4: 75 | L4: 90 | M4: 0 | N4: 0
A5: DEAL00004 | B5: CUST0084 | C5: PROD024 | D5: 679017.38 | E5: 0.0467 | F5: 647326.79 | G5: 537320.32 | H5: 110006.47 | I5: 0.1699 | J5: 0.908 | K5: 41 | L5: 30 | M5: 0 | N5: 1
A6: DEAL00005 | B6: CUST0001 | C6: PROD013 | D6: 5157096 | E6: 0.0963 | F6: 4660692.4 | G6: 3166185.1 | H6: 1494507.3 | I6: 0.3207 | J6: 0.982 | K6: 66 | L6: 45 | M6: 0 | N6: 1
A7: DEAL00006 | B7: CUST0044 | C7: PROD021 | D7: 156611.08 | E7: 0.1059 | F7: 140019.85 | G7: 103384.28 | H7: 36635.57 | I7: 0.2616 | J7: 0.823 | K7: 56 | L7: 30 | M7: 1 | N7: 1
A8: DEAL00007 | B8: CUST0077 | C8: PROD003 | D8: 687164.03 | E8: 0 | F8: 687164.03 | G8: 529502.76 | H8: 157661.27 | I8: 0.2294 | J8: 0.812 | K8: 78 | L8: 30 | M8: 0 | N8: 1
A9: DEAL00008 | B9: CUST0040 | C9: PROD023 | D9: 1792250.5 | E9: 0.0713 | F9: 1664448.5 | G9: 1141138.9 | H9: 523309.6 | I9: 0.3144 | J9: 0.942 | K9: 67 | L9: 45 | M9: 7 | N9: 0
A10: DEAL00009 | B10: CUST0008 | C10: PROD008 | D10: 222365.55 | E10: 0.0983 | F10: 200517.41 | G10: 159029.2 | H10: 41488.21 | I10: 0.2069 | J10: 1.091 | K10: 85 | L10: 30 | M10: 4 | N10: 0
A11: DEAL00010 | B11: CUST0073 | C11: PROD008 | D11: 88946.22 | E11: 0.0928 | F11: 80695.29 | G11: 63611.68 | H11: 17083.61 | I11: 0.2117 | J11: 0.983 | K11: 52 | L11: 30 | M11: 4 | N11: 1
A12: DEAL00011 | B12: CUST0028 | C12: PROD005 | D12: 48628 | E12: 0.1006 | F12: 43735.71 | G12: 32284.33 | H12: 11451.38 | I12: 0.2618 | J12: 1.233 | K12: 24 | L12: 45 | M12: 0 | N12: 1
A13: DEAL00012 | B13: CUST0095 | C13: PROD024 | D13: 2716069.5 | E13: 0.1346 | F13: 2350506.3 | G13: 2149281.3 | H13: 201225 | I13: 0.0856 | J13: 1.094 | K13: 63 | L13: 90 | M13: 0 | N13: 1
... A501: DEAL00500 | B501: CUST0079 | C501: PROD003 | D501: 2748656.1 | E501: 0.0347 | F501: 2653267.4 | G501: 2118011 | H501: 535256.32 | I501: 0.2017 | J501: 0.992 | K501: 88 | L501: 30 | M501: 8 | N501: 1

Sheet Pricing Calculator
A1: Pricing Calculator
A3: Customer Name | B3: IOCL Industries 1
A4: Product Name | B4: Industrial Pump
A5: Quantity | B5: 2
A6: Other Cost (total) | B6: 0
A7: Discount % | B7: 0.1
A8: Competitor Price (total) | B8: 250000
A9: Payment Terms (days) | B9: 45
A10: Expected Delivery (days) | B10: 50
A11: Target Margin % | B11: 0.25
A13: Looked-up Customer & Product Data
A14: Historical Win Rate | B14: =INDEX(Customers!$I$2:$I$101,MATCH($B$3,Customers!$B$2:$B$101,0)) -> 0.4
A15: Relationship Years | B15: =INDEX(Customers!$L$2:$L$101,MATCH($B$3,Customers!$B$2:$B$101,0)) -> 4
A16: Strategic Account (1/0) | B16: =INDEX(Customers!$M$2:$M$101,MATCH($B$3,Customers!$B$2:$B$101,0)) -> 0
A17: Customer Risk Level | B17: =INDEX(Customers!$N$2:$N$101,MATCH($B$3,Customers!$B$2:$B$101,0)) -> Medium
A18: Base Cost (unit) | B18: =INDEX(Products!$D$2:$D$31,MATCH($B$4,Products!$B$2:$B$31,0)) -> 118214.43
A19: Standard Price (unit) | B19: =INDEX(Products!$E$2:$E$31,MATCH($B$4,Products!$B$2:$B$31,0)) -> 191665.7
A20: Installation Cost (unit) | B20: =INDEX(Products!$F$2:$F$31,MATCH($B$4,Products!$B$2:$B$31,0)) -> 7063.14
A21: Warranty Cost (unit) | B21: =INDEX(Products!$G$2:$G$31,MATCH($B$4,Products!$B$2:$B$31,0)) -> 4113.79
A22: Maintenance Cost (unit) | B22: =INDEX(Products!$H$2:$H$31,MATCH($B$4,Products!$B$2:$B$31,0)) -> 3156.89
A23: Logistics Cost (unit) | B23: =INDEX(Products!$I$2:$I$31,MATCH($B$4,Products!$B$2:$B$31,0)) -> 3204.08
A24: Minimum Margin % | B24: =INDEX(Products!$J$2:$J$31,MATCH($B$4,Products!$B$2:$B$31,0)) -> 0.168
A25: Maximum Discount % | B25: =INDEX(Products!$K$2:$K$31,MATCH($B$4,Products!$B$2:$B$31,0)) -> 0.234
A27: Pricing Calculation
A28: Total Cost | B28: =($B$18+$B$20+$B$22+$B$21+$B$23)*$B$5+$B$6 -> 271504.66
A29: List Price | B29: =$B$19*$B$5 -> 383331.4
A30: Discount Amount | B30: =$B$29*$B$7 -> 38333.14
A31: Quoted Price | B31: =$B$29-$B$30 -> 344998.26
A32: Revenue | B32: =$B$31 -> 344998.26
A33: Gross Profit | B33: =$B$32-$B$28 -> 73493.6
A34: Gross Margin % | B34: =IF($B$32=0,0,$B$33/$B$32) -> 0.213026
A35: Minimum Acceptable Price | B35: =$B$28/(1-$B$24) -> 326327.72
A36: Target Price | B36: =$B$28/(1-$B$11) -> 362006.21
A37: Maximum Discount Allowed % | B37: =MAX(0,($B$29-$B$35)/$B$29) -> 0.14870601
A38: Expected Win Probability % (baseline) | B38: =MIN(0.95,MAX(0.03, $B$14 + $B$7*0.6 - (($B$8/$B$31)-1)*0.5 + MIN($B$15,10)*0.005 + IF($B$16=1,0.05,0) - MAX(0,$B$9-45)*0.0007)) -> 0.61767933
A39: Expected Revenue | B39: =$B$32*$B$38 -> 213098.29
A40: Expected Profit | B40: =$B$33*$B$38 -> 45395.478
A42: Commercial Flags
A43: Margin Position | B43: =IF($B$31<$B$35,"Below Minimum Margin",IF($B$31<$B$36,"Competitive",IF($B$31<=$B$36*1.05,"Target Margin Achieved","Premium Pricing"))) -> Competitive
A44: Discount Flag | B44: =IF($B$7>$B$25,"ESCALATION: Discount exceeds maximum allowed",IF($B$7>$B$25*0.6,"Manager approval recommended","Within normal range")) -> Within normal range
...

Sheet Scenario Analysis
A1: Scenario Analysis — Discount Scenarios
A3: All scenarios below reference the Customer/Product/Quantity selected on the Pricing Calculator sheet.
A5: Scenario | B5: Discount % | C5: Quoted Price | D5: Revenue | E5: Total Cost | F5: Gross Profit | G5: Margin % | H5: Win Probability | I5: Expected Revenue | J5: Expected Profit
A6: Scenario A | B6: 0.05 | C6: ='Pricing Calculator'!$B$29*(1-B6) -> 364164.83 | D6: =C6 -> 364164.83 | E6: ='Pricing Calculator'!$B$28 -> 271504.66 | F6: =D6-E6 -> 92660.17 | G6: =IF(D6=0,0,F6/D6) -> 0.25444569 | H6: =MIN(0.95,MAX(0.03, 'Pricing Calculator'!$B$38 + (B6-'Pricing Calculator'!$B$7)*0.6)) -> 0.58767933 | I6: =D6*H6 -> 214012.14 | J6: =F6*H6 -> 54454.467
A7: Scenario B | B7: 0.1 | C7: ='Pricing Calculator'!$B$29*(1-B7) -> 344998.26 | D7: =C7 -> 344998.26 | E7: ='Pricing Calculator'!$B$28 -> 271504.66 | F7: =D7-E7 -> 73493.6 | G7: =IF(D7=0,0,F7/D7) -> 0.213026 | H7: =MIN(0.95,MAX(0.03, 'Pricing Calculator'!$B$38 + (B7-'Pricing Calculator'!$B$7)*0.6)) -> 0.61767933 | I7: =D7*H7 -> 213098.29 | J7: =F7*H7 -> 45395.478
A8: Scenario C | B8: 0.15 | C8: ='Pricing Calculator'!$B$29*(1-B8) -> 325831.69 | D8: =C8 -> 325831.69 | E8: ='Pricing Calculator'!$B$28 -> 271504.66 | F8: =D8-E8 -> 54327.03 | G8: =IF(D8=0,0,F8/D8) -> 0.16673341 | H8: =MIN(0.95,MAX(0.03, 'Pricing Calculator'!$B$38 + (B8-'Pricing Calculator'!$B$7)*0.6)) -> 0.64767933 | I8: =D8*H8 -> 211034.45 | J8: =F8*H8 -> 35186.495
A9: Scenario D | B9: 0.2 | C9: ='Pricing Calculator'!$B$29*(1-B9) -> 306665.12 | D9: =C9 -> 306665.12 | E9: ='Pricing Calculator'!$B$28 -> 271504.66 | F9: =D9-E9 -> 35160.46 | G9: =IF(D9=0,0,F9/D9) -> 0.11465425 | H9: =MIN(0.95,MAX(0.03, 'Pricing Calculator'!$B$38 + (B9-'Pricing Calculator'!$B$7)*0.6)) -> 0.67767933 | I9: =D9*H9 -> 207820.61 | J9: =F9*H9 -> 23827.517
A12: Note: Expected Revenue/Profit = Revenue or Gross Profit x Win Probability (simplified expected-value approach).

Sheet Risk Assessment
A1: Commercial Risk Assessment
A3: Risk Weights (editable, must total 100%)
A4: Customer Risk | B4: 0.15 | D4: Score each dimension 0 (Low), 1 (Medium), 2 (High):
A5: Payment Risk | B5: 0.15 | D5: Customer Risk | E5: 1
A6: Margin Risk | B6: 0.2 | D6: Payment Risk | E6: 1
A7: Discount Risk | B7: 0.15 | D7: Margin Risk | E7: 1
A8: Delivery Risk | B8: 0.1 | D8: Discount Risk | E8: 1
A9: Warranty Risk | B9: 0.1 | D9: Delivery Risk | E9: 0
A10: Competitive Risk | B10: 0.1 | D10: Warranty Risk | E10: 0
A11: Contract Risk | B11: 0.05 | D11: Competitive Risk | E11: 1
A12: Total | B12: =SUM(B4:B11) -> 1 | D12: Contract Risk | E12: 0
A14: Weighted Risk Score (0-100) | B14: =(E5/2)*100*B4+(E6/2)*100*B5+(E7/2)*100*B6+(E8/2)*100*B7+(E9/2)*100*B8+(E10/2)*100*B9+(E11/2)*100*B10+(E12/2)*100*B11 -> 37.5
A15: Risk Classification | B15: =IF(B14<=30,"Low",IF(B14<=60,"Medium","High")) -> Medium

Sheet Proposal Summary
A1: Proposal Summary
A3: Customer | B3: ='Pricing Calculator'!$B$3 -> IOCL Industries 1
A4: Product | B4: ='Pricing Calculator'!$B$4 -> Industrial Pump
A5: Quantity | B5: ='Pricing Calculator'!$B$5 -> 2
A6: Quoted Price | B6: ='Pricing Calculator'!$B$31 -> 344998.26
A7: Discount % | B7: ='Pricing Calculator'!$B$7 -> 0.1
A8: Total Contract Value | B8: ='Pricing Calculator'!$B$31 -> 344998.26
A9: Expected Margin % | B9: ='Pricing Calculator'!$B$34 -> 0.213026
A10: Payment Terms (days) | B10: ='Pricing Calculator'!$B$9 -> 45
A11: Expected Delivery (days) | B11: ='Pricing Calculator'!$B$10 -> 50
A12: Win Probability | B12: ='Pricing Calculator'!$B$38 -> 0.61767933
A13: Margin Position | B13: ='Pricing Calculator'!$B$43 -> Competitive
A14: Margin Flag | B14: ='Pricing Calculator'!$B$45 -> AMBER: Below target margin
A17: This summary updates automatically when inputs on the Pricing Calculator sheet change.
